Workbook

Sheet Assumptions
A1: AoBPlatform — Cash Model Assumptions
A2: Every blue cell is an input. Yellow cells are the levers that move the answer most. All figures in AUD.
A3: Legend: blue = input you can change · black = calculated · green = pulled from another sheet · yellow fill = key lever
A4: SCENARIO (1 = Base 2 = Lean team 3 = Lean + more adoption 4 = Realistic upside) | B4: 4 | D4: Change this one cell to switch the whole model. Everything below with a formula follows it.
A5: MARKET
A6: General practices in Australia (accredited) | B6: 7132 | D6: RACGP Health of the Nation 2025
A7: Average billing practitioners per GP practice | B7: 5 | D7: 40,375 GPs / 7,132 practices, rounded down for part-time
A8: Target non-GP practices (allied, optometry, specialist) | B8: 12000 | D8: Estimate — no published practice count exists for these segments
A9: Average billing practitioners per non-GP practice | B9: 2.5 | D9: Estimate
A11: PRICING
A12: Core subscription — GP ($ per practitioner per month) | B12: =INDEX(B53:E53,$B$4) -> 49 | D12: vs Bp Premier ~$124/mo per FT doctor and HotDoc from ~$85/practitioner/mo
A13: Core subscription — non-GP ($ per practitioner per month) | B13: =INDEX(B54:E54,$B$4) -> 29 | D13: Lower ability to pay in allied and solo practice
A14: Managed follow-up ($ per practice per month) | B14: =INDEX(B55:E55,$B$4) -> 400 | D14: Priced against staff time, not against software
A15: Managed follow-up attach rate (% of GP practices) | B15: =INDEX(B56:E56,$B$4) -> 0.55 | D15: Assumption
A16: Enduring enrolment ($ per completed agreement) | B16: 2 | D16: One-off, in the year after a GP practice onboards
A17: Enduring agreements per GP practice (one-off campaign) | B17: 1500 | D17: Per practitioner, so a multiple of patients — see Addendum v3
A18: Audit response ($ per engagement) | B18: 2500 | D18: Low volume, high value
A19: Audit engagements (% of installed base per year) | B19: 0.03 | D19: Assumption
A20: Recall campaigns — price per extra campaign ($) | B20: 199 | D20: Practice-funded outreach (flu clinics, screening, MyMedicare drives); one/quarter included
A21: Paid extra campaigns per practice per year (avg) | B21: 1.5 | D21: Assumption — beyond the included quarterly campaign
A23: ADOPTION — new practices won during the year
A24: Financial year (Australian, ending 30 June) | B24: FY27 | C24: FY28 | D24: FY29 | E24: FY30 | F24: FY31
A25: New GP practices won | B25: =INDEX(B57:E57,$B$4) -> 60 | C25: =INDEX(B58:E58,$B$4) -> 300 | D25: =INDEX(B59:E59,$B$4) -> 700 | E25: =INDEX(B60:E60,$B$4) -> 950 | F25: =INDEX(B61:E61,$B$4) -> 1100
A26: New non-GP practices won | B26: =INDEX(B62:E62,$B$4) -> 20 | C26: =INDEX(B63:E63,$B$4) -> 150 | D26: =INDEX(B64:E64,$B$4) -> 450 | E26: =INDEX(B65:E65,$B$4) -> 760 | F26: =INDEX(B66:E66,$B$4) -> 1030
A27: Annual practice churn (%) | B27: 0.05 | C27: 0.08 | D27: 0.1 | E27: 0.1 | F27: 0.1
A29: COST OF DELIVERY
A30: Messaging and infrastructure ($ per practitioner per month) | B30: 3.5 | D30: SMS at ~4c plus hosting; most capture is in-practice so remote volume is low
A31: Managed follow-up — delivery cost (% of that revenue) | B31: 0.45 | D31: AI-led with a small human team for escalation
A32: Enrolment campaigns — delivery cost (% of that revenue) | B32: 0.25 | D32: Largely automated
A33: Audit response — delivery cost (% of that revenue) | B33: 0.4 | D33: Human-delivered
A35: OPERATING COSTS
A36: Financial year | B36: FY27 | C36: FY28 | D36: FY29 | E36: FY30 | F36: FY31
A37: Headcount at year end (FTE) | B37: =INDEX(B67:E67,$B$4) -> 8 | C37: =INDEX(B68:E68,$B$4) -> 16 | D37: =INDEX(B69:E69,$B$4) -> 24 | E37: =INDEX(B70:E70,$B$4) -> 30 | F37: =INDEX(B71:E71,$B$4) -> 36
A38: Average fully loaded cost per FTE ($) | B38: 150000 | C38: 154500 | D38: 159135 | E38: 163909 | F38: 168826
A39: Sales and marketing (% of revenue, floor applies below) | B39: 0.3 | C39: 0.25 | D39: 0.2 | E39: 0.16 | F39: 0.14
A40: Sales and marketing floor ($) | B40: 350000 | C40: 600000 | D40: 900000 | E40: 1200000 | F40: 1400000
A41: Security, compliance and assurance ($) | B41: 140000 | C41: 200000 | D41: 240000 | E41: 270000 | F41: 300000
A42: Other general and administrative ($ per FTE) | B42: 9000 | C42: 9000 | D42: 9500 | E42: 9500 | F42: 10000
A44: WORKING CAPITAL AND FUNDING
A45: Debtor days (subscription and services) | B45: 30 | D45: Practices pay monthly in arrears
...

Sheet Model
A1: AoBPlatform — Five Year Model
A2: All figures in AUD. Australian financial years ending 30 June. Green figures are pulled from Assumptions.
A4: Financial year | B4: FY27 | C4: FY28 | D4: FY29 | E4: FY30 | F4: FY31
A5: INSTALLED BASE
A6: GP practices — opening | B6: =0 -> 0 | C6: =B8 -> 57 | D6: =C8 -> 328.44 | E6: =D8 -> 925.596 | F6: =E8 -> 1688.0364
A7: GP practices — won | B7: =Assumptions!B25 -> 60 | C7: =Assumptions!C25 -> 300 | D7: =Assumptions!D25 -> 700 | E7: =Assumptions!E25 -> 950 | F7: =Assumptions!F25 -> 1100
A8: GP practices — closing | B8: =(B6+B7)*(1-Assumptions!B27) -> 57 | C8: =(C6+C7)*(1-Assumptions!C27) -> 328.44 | D8: =(D6+D7)*(1-Assumptions!D27) -> 925.596 | E8: =(E6+E7)*(1-Assumptions!E27) -> 1688.0364 | F8: =(F6+F7)*(1-Assumptions!F27) -> 2509.2328
A9: Non-GP practices — opening | B9: =0 -> 0 | C9: =B11 -> 19 | D9: =C11 -> 155.48 | E9: =D11 -> 544.932 | F9: =E11 -> 1174.4388
A10: Non-GP practices — won | B10: =Assumptions!B26 -> 20 | C10: =Assumptions!C26 -> 150 | D10: =Assumptions!D26 -> 450 | E10: =Assumptions!E26 -> 760 | F10: =Assumptions!F26 -> 1030
A11: Non-GP practices — closing | B11: =(B9+B10)*(1-Assumptions!B27) -> 19 | C11: =(C9+C10)*(1-Assumptions!C27) -> 155.48 | D11: =(D9+D10)*(1-Assumptions!D27) -> 544.932 | E11: =(E9+E10)*(1-Assumptions!E27) -> 1174.4388 | F11: =(F9+F10)*(1-Assumptions!F27) -> 1983.9949
A12: GP practices — average during year | B12: =(B6+B8)/2 -> 28.5 | C12: =(C6+C8)/2 -> 192.72 | D12: =(D6+D8)/2 -> 627.018 | E12: =(E6+E8)/2 -> 1306.8162 | F12: =(F6+F8)/2 -> 2098.6346
A13: Non-GP practices — average during year | B13: =(B9+B11)/2 -> 9.5 | C13: =(C9+C11)/2 -> 87.24 | D13: =(D9+D11)/2 -> 350.206 | E13: =(E9+E11)/2 -> 859.6854 | F13: =(F9+F11)/2 -> 1579.2169
A14: Billing practitioners on the platform (average) | B14: =B12*Assumptions!$B$7+B13*Assumptions!$B$9 -> 166.25 | C14: =C12*Assumptions!$B$7+C13*Assumptions!$B$9 -> 1181.7 | D14: =D12*Assumptions!$B$7+D13*Assumptions!$B$9 -> 4010.605 | E14: =E12*Assumptions!$B$7+E13*Assumptions!$B$9 -> 8683.2945 | F14: =F12*Assumptions!$B$7+F13*Assumptions!$B$9 -> 14441.215
A16: REVENUE
A17: Core subscription — GP | B17: =B12*Assumptions!$B$7*Assumptions!$B$12*12 -> 83790 | C17: =C12*Assumptions!$B$7*Assumptions!$B$12*12 -> 566596.8 | D17: =D12*Assumptions!$B$7*Assumptions!$B$12*12 -> 1843432.9 | E17: =E12*Assumptions!$B$7*Assumptions!$B$12*12 -> 3842039.6 | F17: =F12*Assumptions!$B$7*Assumptions!$B$12*12 -> 6169985.7
A18: Core subscription — non-GP | B18: =B13*Assumptions!$B$9*Assumptions!$B$13*12 -> 8265 | C18: =C13*Assumptions!$B$9*Assumptions!$B$13*12 -> 75898.8 | D18: =D13*Assumptions!$B$9*Assumptions!$B$13*12 -> 304679.22 | E18: =E13*Assumptions!$B$9*Assumptions!$B$13*12 -> 747926.3 | F18: =F13*Assumptions!$B$9*Assumptions!$B$13*12 -> 1373918.7
A19: Managed follow-up | B19: =B12*Assumptions!$B$15*Assumptions!$B$14*12 -> 75240 | C19: =C12*Assumptions!$B$15*Assumptions!$B$14*12 -> 508780.8 | D19: =D12*Assumptions!$B$15*Assumptions!$B$14*12 -> 1655327.5 | E19: =E12*Assumptions!$B$15*Assumptions!$B$14*12 -> 3449994.8 | F19: =F12*Assumptions!$B$15*Assumptions!$B$14*12 -> 5540395.3
A20: Enduring enrolment campaigns | B20: =0 -> 0 | C20: =Assumptions!B25*Assumptions!$B$17*Assumptions!$B$16 -> 180000 | D20: =Assumptions!C25*Assumptions!$B$17*Assumptions!$B$16 -> 900000 | E20: =Assumptions!D25*Assumptions!$B$17*Assumptions!$B$16 -> 2100000 | F20: =Assumptions!E25*Assumptions!$B$17*Assumptions!$B$16 -> 2850000
A21: Audit response | B21: =(B12+B13)*Assumptions!$B$19*Assumptions!$B$18 -> 2850 | C21: =(C12+C13)*Assumptions!$B$19*Assumptions!$B$18 -> 20997 | D21: =(D12+D13)*Assumptions!$B$19*Assumptions!$B$18 -> 73291.8 | E21: =(E12+E13)*Assumptions!$B$19*Assumptions!$B$18 -> 162487.62 | F21: =(F12+F13)*Assumptions!$B$19*Assumptions!$B$18 -> 275838.86
A22: Recall campaigns | B22: =(B12+B13)*Assumptions!$B$21*Assumptions!$B$20 -> 11343 | C22: =(C12+C13)*Assumptions!$B$21*Assumptions!$B$20 -> 83568.06 | D22: =(D12+D13)*Assumptions!$B$21*Assumptions!$B$20 -> 291701.36 | E22: =(E12+E13)*Assumptions!$B$21*Assumptions!$B$20 -> 646700.73 | F22: =(F12+F13)*Assumptions!$B$21*Assumptions!$B$20 -> 1097838.7
A23: Total revenue | B23: =SUM(B17:B22) -> 181488 | C23: =SUM(C17:C22) -> 1435841.5 | D23: =SUM(D17:D22) -> 5068432.8 | E23: =SUM(E17:E22) -> 10949149 | F23: =SUM(F17:F22) -> 17307977
A24: Revenue growth | B24: - | C24: =IFERROR(C23/B23-1,0) -> 6.9114953 | D24: =IFERROR(D23/C23-1,0) -> 2.529939 | E24: =IFERROR(E23/D23-1,0) -> 1.1602632 | F24: =IFERROR(F23/E23-1,0) -> 0.58076003
A26: COST OF DELIVERY
A27: Messaging and infrastructure | B27: =-B14*Assumptions!$B$30*12 -> -6982.5 | C27: =-C14*Assumptions!$B$30*12 -> -49631.4 | D27: =-D14*Assumptions!$B$30*12 -> -168445.41 | E27: =-E14*Assumptions!$B$30*12 -> -364698.37 | F27: =-F14*Assumptions!$B$30*12 -> -606531.03
A28: Managed follow-up delivery | B28: =-B19*Assumptions!$B$31 -> -33858 | C28: =-C19*Assumptions!$B$31 -> -228951.36 | D28: =-D19*Assumptions!$B$31 -> -744897.38 | E28: =-E19*Assumptions!$B$31 -> -1552497.6 | F28: =-F19*Assumptions!$B$31 -> -2493177.9
A29: Enrolment campaign delivery | B29: =-B20*Assumptions!$B$32 -> 0 | C29: =-C20*Assumptions!$B$32 -> -45000 | D29: =-D20*Assumptions!$B$32 -> -225000 | E29: =-E20*Assumptions!$B$32 -> -525000 | F29: =-F20*Assumptions!$B$32 -> -712500
A30: Audit response delivery | B30: =-B21*Assumptions!$B$33 -> -1140 | C30: =-C21*Assumptions!$B$33 -> -8398.8 | D30: =-D21*Assumptions!$B$33 -> -29316.72 | E30: =-E21*Assumptions!$B$33 -> -64995.048 | F30: =-F21*Assumptions!$B$33 -> -110335.54
A31: Recall campaign delivery | B31: =-B22*0.25 -> -2835.75 | C31: =-C22*0.25 -> -20892.015 | D31: =-D22*0.25 -> -72925.341 | E31: =-E22*0.25 -> -161675.18 | F31: =-F22*0.25 -> -274459.66
A32: Total cost of delivery | B32: =SUM(B27:B31) -> -44816.25 | C32: =SUM(C27:C31) -> -352873.58 | D32: =SUM(D27:D31) -> -1240584.9 | E32: =SUM(E27:E31) -> -2668866.2 | F32: =SUM(F27:F31) -> -4197004.1
A33: Gross profit | B33: =B23+B32 -> 136671.75 | C33: =C23+C32 -> 1082967.9 | D33: =D23+D32 -> 3827848 | E33: =E23+E32 -> 8280282.8 | F33: =F23+F32 -> 13110973
A34: Gross margin | B34: =IFERROR(B33/B23,0) -> 0.75306219 | C34: =IFERROR(C33/C23,0) -> 0.75423918 | D34: =IFERROR(D33/D23,0) -> 0.75523305 | E34: =IFERROR(E33/E23,0) -> 0.75624898 | F34: =IFERROR(F33/F23,0) -> 0.75751042
A36: OPERATING COSTS
A37: People | B37: =-Assumptions!B37*Assumptions!B38 -> -1200000 | C37: =-Assumptions!C37*Assumptions!C38 -> -2472000 | D37: =-Assumptions!D37*Assumptions!D38 -> -3819240 | E37: =-Assumptions!E37*Assumptions!E38 -> -4917270 | F37: =-Assumptions!F37*Assumptions!F38 -> -6077736
A38: Sales and marketing | B38: =-MAX(B23*Assumptions!B39,Assumptions!B40) -> -350000 | C38: =-MAX(C23*Assumptions!C39,Assumptions!C40) -> -600000 | D38: =-MAX(D23*Assumptions!D39,Assumptions!D40) -> -1013686.6 | E38: =-MAX(E23*Assumptions!E39,Assumptions!E40) -> -1751863.8 | F38: =-MAX(F23*Assumptions!F39,Assumptions!F40) -> -2423116.8
A39: Security, compliance and assurance | B39: =-Assumptions!B41 -> -140000 | C39: =-Assumptions!C41 -> -200000 | D39: =-Assumptions!D41 -> -240000 | E39: =-Assumptions!E41 -> -270000 | F39: =-Assumptions!F41 -> -300000
A40: Other general and administrative | B40: =-Assumptions!B37*Assumptions!B42 -> -72000 | C40: =-Assumptions!C37*Assumptions!C42 -> -144000 | D40: =-Assumptions!D37*Assumptions!D42 -> -228000 | E40: =-Assumptions!E37*Assumptions!E42 -> -285000 | F40: =-Assumptions!F37*Assumptions!F42 -> -360000
A41: Total operating costs | B41: =SUM(B37:B40) -> -1762000 | C41: =SUM(C37:C40) -> -3416000 | D41: =SUM(D37:D40) -> -5300926.6 | E41: =SUM(E37:E40) -> -7224133.8 | F41: =SUM(F37:F40) -> -9160852.8
A42: EBITDA | B42: =B33+B41 -> -1625328.2 | C42: =C33+C41 -> -2333032.1 | D42: =D33+D41 -> -1473078.6 | E42: =E33+E41 -> 1056149 | F42: =F33+F41 -> 3950120.2
A43: EBITDA margin | B43: =IFERROR(B42/B23,0) -> -8.9555687 | C43: =IFERROR(C42/C23,0) -> -1.6248536 | D43: =IFERROR(D42/D23,0) -> -0.29063788 | E43: =IFERROR(E42/E23,0) -> 0.096459455 | F43: =IFERROR(F42/F23,0) -> 0.22822541
A45: BELOW EBITDA
...

Sheet Unit Economics
A1: Unit economics — one average GP practice
A2: The number that decides whether this is a business. All figures in AUD.
A4: Billing practitioners per practice | B4: =Assumptions!$B$7 -> 5 | D4: From Assumptions
A5: Core subscription per year | B5: =B4*Assumptions!$B$12*12 -> 2940 | D5: Practitioners x monthly price x 12
A6: Managed follow-up per year (expected, at attach rate) | B6: =Assumptions!$B$14*12*Assumptions!$B$15 -> 2640 | D6: Weighted by the share of practices that take it
A7: Enduring enrolment (one-off, year two) | B7: =Assumptions!$B$17*Assumptions!$B$16 -> 3000 | D7: Non-recurring
A8: Audit response per year (expected) | B8: =Assumptions!$B$18*Assumptions!$B$19 -> 75 | D8: Weighted by frequency
A9: Recurring revenue per practice per year | B9: =B5+B6+B8 -> 5655 | D9: Excludes the one-off enrolment campaign
A10: Cost of delivery per practice per year | B10: =-(B4*Assumptions!$B$30*12 + Assumptions!$B$14*12*Assumptions!$B$15*Assumptions!$B$31 + Assumptions!$B$18*Assumptions!$B$19*Assumptions!$B$33) -> -1428 | D10: Messaging, infrastructure and service delivery
A11: Gross profit per practice per year | B11: =B9+B10 -> 4227
A12: Gross margin | B12: =IFERROR(B11/B9,0) -> 0.74748011
A13: Customer acquisition cost | B13: =IFERROR(-Model!C38/(Assumptions!C25+Assumptions!C26),0) -> 1333.3333 | D13: FY28 sales and marketing divided by practices won that year
A14: Months to recover acquisition cost | B14: =IFERROR(B13/(B11/12),0) -> 3.7851904 | D14: Gross-profit payback
A15: Average customer life (years) | B15: =IFERROR(1/Assumptions!$D$27,0) -> 10 | D15: One divided by the steady-state churn rate
A16: Lifetime gross profit per practice | B16: =B11*B15 -> 42270
A17: Lifetime value to acquisition cost | B17: =IFERROR(B16/B13,0) -> 31.7025 | D17: Below 3.0x the model does not work
A20: The comparison that matters
A21: Modelled saving per FTE GP per year (steady state) | B21: 1400 | D21: From the published advisory estimate of ~$1,750 per FTE GP per year, most of which is chase labour
A22: Our recurring price per practitioner per year | B22: =Assumptions!$B$12*12 -> 588
A23: Share of the saving we capture | B23: =IFERROR(B22/B21,0) -> 0.42 | D23: Well under half. If this exceeds ~50% the sale gets hard.

Sheet Scenarios
A1: Scenarios — full profit and loss, down to net profit after tax
A2: Now includes recall-campaign revenue (1.5 paid campaigns per practice per year at $199, 25% delivery cost). Tax at 25% after carried-forward losses.
A4: Scenario | B4: FY27 | C4: FY28 | D4: FY29 | E4: FY30 | F4: FY31
A5: BASE — as built on the Model tab
A6: Headcount 9/20/36/54/70. $39 per practitioner. Follow-up $350 at 35% attach. Incl. recall campaigns.
A7: Revenue | B7: 97427 | C7: 802280 | D7: 2888498 | E7: 6312352 | F7: 9868338
A8: EBITDA | B8: -1845931 | C8: -3453789 | D8: -4993829 | E8: -5987402 | F8: -6625985
A9: Depreciation and amortisation | B9: -12000 | C9: -38667 | D9: -86667 | E9: -146667 | F9: -213333
A10: EBIT / profit before tax | B10: -1857931 | C10: -3492456 | D10: -5080496 | E10: -6134069 | F10: -6839318
A11: Company tax at 25% | B11: 0 | C11: 0 | D11: 0 | E11: 0 | F11: 0
A12: NET PROFIT AFTER TAX | B12: -1857931 | C12: -3492456 | D12: -5080496 | E12: -6134069 | F12: -6839318
A13: Carried-forward tax losses at year end | B13: 1857931 | C13: 5350387 | D13: 10430883 | E13: 16564952 | F13: 23404270
A14: Cumulative net profit after tax | B14: -1857931 | C14: -5350387 | D14: -10430883 | E14: -16564952 | F14: -23404270
A16: LEAN — headcount 8/16/24/30/36
A17: Same price, same adoption. Only the team is smaller.
A18: Revenue | B18: 97427 | C18: 802280 | D18: 2888498 | E18: 6312352 | F18: 9868338
A19: EBITDA | B19: -1686931 | C19: -2799789 | D19: -2970209 | E19: -1825586 | F19: -545901
A20: Depreciation and amortisation | B20: -10667 | C20: -32000 | D20: -64000 | E20: -93333 | F20: -120000
A21: EBIT / profit before tax | B21: -1697598 | C21: -2831789 | D21: -3034209 | E21: -1918920 | F21: -665901
A22: Company tax at 25% | B22: 0 | C22: 0 | D22: 0 | E22: 0 | F22: 0
A23: NET PROFIT AFTER TAX | B23: -1697598 | C23: -2831789 | D23: -3034209 | E23: -1918920 | F23: -665901
A24: Carried-forward tax losses at year end | B24: 1697598 | C24: 4529387 | D24: 7563596 | E24: 9482516 | F24: 10148417
A25: Cumulative net profit after tax | B25: -1697598 | C25: -4529387 | D25: -7563596 | E25: -9482516 | F25: -10148417
A27: LEAN + 50% MORE ADOPTION
A28: Lean team, base pricing, half again as many practices won each year.
A29: Revenue | B29: 129903 | C29: 1084258 | D29: 3916586 | E29: 8532922 | F29: 13403888
A30: EBITDA | B30: -1661908 | C30: -2583148 | D30: -2181114 | E30: -285443 | F30: 1697535
A31: Depreciation and amortisation | B31: -10667 | C31: -32000 | D31: -64000 | E31: -93333 | F31: -120000
A32: EBIT / profit before tax | B32: -1672575 | C32: -2615148 | D32: -2245114 | E32: -378776 | F32: 1577535
A33: Company tax at 25% | B33: 0 | C33: 0 | D33: 0 | E33: 0 | F33: 0
A34: NET PROFIT AFTER TAX | B34: -1672575 | C34: -2615148 | D34: -2245114 | E34: -378776 | F34: 1577535
A35: Carried-forward tax losses at year end | B35: 1672575 | C35: 4287723 | D35: 6532837 | E35: 6911613 | F35: 5334078
A36: Cumulative net profit after tax | B36: -1672575 | C36: -4287723 | D36: -6532837 | E36: -6911613 | F36: -5334078
A38: REALISTIC UPSIDE
A39: Lean team. $49 per practitioner. Follow-up $400 at 55% attach. 50% more adoption. Incl. recall campaigns.
A40: Revenue | B40: 181488 | C40: 1435841 | D40: 5068433 | E40: 10949149 | F40: 17307977
A41: EBITDA | B41: -1625328 | C41: -2333032 | D41: -1473079 | E41: 1056149 | F41: 3950120
A42: Depreciation and amortisation | B42: -10667 | C42: -32000 | D42: -64000 | E42: -93333 | F42: -120000
A43: EBIT / profit before tax | B43: -1635995 | C43: -2365032 | D43: -1537079 | E43: 962816 | F43: 3830120
A44: Company tax at 25% | B44: 0 | C44: 0 | D44: 0 | E44: 0 | F44: 0
...

Sheet Sensitivity
A1: Sensitivity — what actually moves the answer
A2: Capital to raise, at varying price and adoption. Change the Assumptions tab to move the base case.
A4: Base case capital to raise | B4: =Model!B71 -> 6252364
A6: The three levers, in order of impact
A7: 1. Adoption rate | B7: New practices won each year | D7: Halving adoption roughly doubles the time to break even and increases the raise. This is the single largest driver and the least controllable.
A8: 2. Managed follow-up attach rate | B8: Share of practices taking the service | D8: Highest-margin recurring line after core subscription, and it is the offering competitors cannot bundle.
A9: 3. Price per practitioner | B9: Core subscription | D9: We capture well under half the modelled saving, so there is headroom — but the two large distributors bundle a form at zero marginal cost, so price is not where this is won.
A12: To run a scenario: change the yellow cells on the Assumptions tab and read the capital to raise above.
A14: Known weaknesses in this model
A15: Adoption is assumed, not tested. No practice has paid anything.
A16: Churn is a flat annual rate. Real churn is front-loaded in year one.
A17: The managed follow-up margin assumes AI handles most contacts. That is unproven.
A18: Enduring enrolment revenue is one-off and does not repeat — it flatters year two.
A19: Non-GP practice count is an estimate. No published figure exists for those segments.
A20: No allowance for a failed security review, a lost integration, or a regulatory reversal — all of which have precedent.
A21: A lifetime-value-to-acquisition-cost ratio above about 5x almost always means the churn or acquisition-cost assumption is too kind. Treat the figure on the Unit Economics tab as an upper bound.
A22: Enduring agreements cut the number of agreements while increasing post-claim notice volume. Pricing per practitioner rather than per agreement is what keeps those two forces from working against you.
