Workbook

Sheet Assumptions
A1: NDIS Consent & Evidence Platform — Cash Model Assumptions
A2: Separate product, separate model. Blue = input. Yellow = the levers that move the answer most. AUD. Years are years from launch.
A3: Legend: blue = input · black = calculated · green = link to another sheet · yellow = key lever · grey = driven by the scenario switch in B4
A4: SCENARIO (1 = Standalone base 2 = Standalone lean 3 = Shared engine 4 = Shared engine + plan-manager channel) | B4: 4 | D4: Change this one cell; the Model tab follows. Scenarios 3–4 assume the AoB engine already exists (smaller team).
A6: MARKET
A7: Registered therapy providers (orgs) | B7: 7274 | D7: NDIA Annual Pricing Review 2026-27 via Conway Group — verify against primary
A8: Unregistered therapy providers (solos) | B8: 46330 | D8: Same source; avg $22k NDIS billings each
A9: Registered non-therapy providers (support/SIL orgs) | B9: 10000 | D9: ~17,374 registered minus therapy — ESTIMATE
A10: Plan management businesses | B10: 1100 | D10: ESTIMATE — verify with Disability Intermediaries Australia
A11: Practitioners per therapy org (avg) | B11: 3 | D11: Assumption
A13: PRICING ($ per customer per month)
A14: Therapy org — per practitioner per month | B14: 45 | D14: Signed support logs, service agreements, 7-yr retention, reconciliation
A15: Solo therapy provider — flat per month | B15: 19 | D15: Self-serve tier; they bill only ~$22k/yr of NDIS
A16: Support/SIL org — average per month (tiered by workforce) | B16: 600 | D16: 0.2–0.5% of a typical org’s NDIS revenue; anchored against Lumary/ShiftCare spend
A17: Plan manager — per month | B17: =INDEX(B50:E50,$B$4) -> 1250 | D17: Evidence verification on invoices from unregistered providers
A19: ADOPTION — new customers won during the year
A20: Year from launch | B20: Y1 | C20: Y2 | D20: Y3 | E20: Y4 | F20: Y5
A21: New therapy orgs won | B21: =INDEX(B51:E51,$B$4) -> 30 | C21: =INDEX(B52:E52,$B$4) -> 150 | D21: =INDEX(B53:E53,$B$4) -> 400 | E21: =INDEX(B54:E54,$B$4) -> 700 | F21: =INDEX(B55:E55,$B$4) -> 900
A22: New solo providers won | B22: =INDEX(B56:E56,$B$4) -> 80 | C22: =INDEX(B57:E57,$B$4) -> 600 | D22: =INDEX(B58:E58,$B$4) -> 2200 | E22: =INDEX(B59:E59,$B$4) -> 4200 | F22: =INDEX(B60:E60,$B$4) -> 6000
A23: New support/SIL orgs won | B23: =INDEX(B61:E61,$B$4) -> 10 | C23: =INDEX(B62:E62,$B$4) -> 60 | D23: =INDEX(B63:E63,$B$4) -> 180 | E23: =INDEX(B64:E64,$B$4) -> 350 | F23: =INDEX(B65:E65,$B$4) -> 500
A24: New plan managers won | B24: =INDEX(B66:E66,$B$4) -> 12 | C24: =INDEX(B67:E67,$B$4) -> 40 | D24: =INDEX(B68:E68,$B$4) -> 90 | E24: =INDEX(B69:E69,$B$4) -> 150 | F24: =INDEX(B70:E70,$B$4) -> 210
A25: Annual customer churn (%) | B25: 0.08 | C25: 0.1 | D25: 0.12 | E25: 0.12 | F25: 0.12
A27: COST OF DELIVERY
A28: Blended delivery cost (% of revenue) | B28: 0.18 | D28: Messaging, storage, support; capture is mostly in-person at point of support
A29: Infrastructure floor ($ per year) | B29: 70000 | D29: HSM, logging, environments — fixed from day one
A31: OPERATING COSTS
A32: Year from launch | B32: Y1 | C32: Y2 | D32: Y3 | E32: Y4 | F32: Y5
A33: Headcount at year end (FTE) | B33: =INDEX(B71:E71,$B$4) -> 4 | C33: =INDEX(B72:E72,$B$4) -> 8 | D33: =INDEX(B73:E73,$B$4) -> 13 | E33: =INDEX(B74:E74,$B$4) -> 17 | F33: =INDEX(B75:E75,$B$4) -> 21
A34: Average fully loaded cost per FTE ($) | B34: 150000 | C34: 154500 | D34: 159135 | E34: 163909 | F34: 168826
A35: Sales and marketing (% of revenue, floor below) | B35: 0.3 | C35: 0.25 | D35: 0.2 | E35: 0.16 | F35: 0.14
A36: Sales and marketing floor ($) | B36: 300000 | C36: 500000 | D36: 750000 | E36: 1000000 | F36: 1200000
A37: Security, compliance and assurance ($) | B37: 120000 | C37: 160000 | D37: 200000 | E37: 230000 | F37: 260000
A38: Other general and administrative ($ per FTE) | B38: 9000 | C38: 9000 | D38: 9500 | E38: 9500 | F38: 10000
A40: WORKING CAPITAL, TAX AND FUNDING
A41: Debtor days | B41: 35 | D41: NDIS invoices pay slower than card subscriptions
A42: Creditor days | B42: 30 | D42: Assumption
A43: Opening cash ($) | B43: 0 | D43: Set to actual
A44: Cash buffer on top of peak deficit ($) | B44: 600000 | D44: ~6 months of trough run rate
A45: Equipment per FTE ($) | B45: 4000 | D45: Laptops, devices
A46: Asset life (years) | B46: 3 | D46: Straight line
...

Sheet Model
A1: NDIS Platform — Five Year Model
A2: All figures AUD. Years from launch. Green = pulled from Assumptions. Driven by the scenario switch (Assumptions B4).
A4: Year from launch | B4: Y1 | C4: Y2 | D4: Y3 | E4: Y4 | F4: Y5
A5: INSTALLED BASE (closing, after churn)
A6: Therapy orgs — closing | B6: =(0+Assumptions!B21)*(1-Assumptions!B25) -> 27.6 | C6: =(B6+Assumptions!C21)*(1-Assumptions!C25) -> 159.84 | D6: =(C6+Assumptions!D21)*(1-Assumptions!D25) -> 492.6592 | E6: =(D6+Assumptions!E21)*(1-Assumptions!E25) -> 1049.5401 | F6: =(E6+Assumptions!F21)*(1-Assumptions!F25) -> 1715.5953
A7: Solo providers — closing | B7: =(0+Assumptions!B22)*(1-Assumptions!B25) -> 73.6 | C7: =(B7+Assumptions!C22)*(1-Assumptions!C25) -> 606.24 | D7: =(C7+Assumptions!D22)*(1-Assumptions!D25) -> 2469.4912 | E7: =(D7+Assumptions!E22)*(1-Assumptions!E25) -> 5869.1523 | F7: =(E7+Assumptions!F22)*(1-Assumptions!F25) -> 10444.854
A8: Support/SIL orgs — closing | B8: =(0+Assumptions!B23)*(1-Assumptions!B25) -> 9.2 | C8: =(B8+Assumptions!C23)*(1-Assumptions!C25) -> 62.28 | D8: =(C8+Assumptions!D23)*(1-Assumptions!D25) -> 213.2064 | E8: =(D8+Assumptions!E23)*(1-Assumptions!E25) -> 495.62163 | F8: =(E8+Assumptions!F23)*(1-Assumptions!F25) -> 876.14704
A9: Plan managers — closing | B9: =(0+Assumptions!B24)*(1-Assumptions!B25) -> 11.04 | C9: =(B9+Assumptions!C24)*(1-Assumptions!C25) -> 45.936 | D9: =(C9+Assumptions!D24)*(1-Assumptions!D25) -> 119.62368 | E9: =(D9+Assumptions!E24)*(1-Assumptions!E25) -> 237.26884 | F9: =(E9+Assumptions!F24)*(1-Assumptions!F25) -> 393.59658
A10: Therapy orgs — average during year | B10: =(0+B6)/2 -> 13.8 | C10: =(B6+C6)/2 -> 93.72 | D10: =(C6+D6)/2 -> 326.2496 | E10: =(D6+E6)/2 -> 771.09965 | F10: =(E6+F6)/2 -> 1382.5677
A11: Solo providers — average during year | B11: =(0+B7)/2 -> 36.8 | C11: =(B7+C7)/2 -> 339.92 | D11: =(C7+D7)/2 -> 1537.8656 | E11: =(D7+E7)/2 -> 4169.3217 | F11: =(E7+F7)/2 -> 8157.0031
A12: Support/SIL orgs — average during year | B12: =(0+B8)/2 -> 4.6 | C12: =(B8+C8)/2 -> 35.74 | D12: =(C8+D8)/2 -> 137.7432 | E12: =(D8+E8)/2 -> 354.41402 | F12: =(E8+F8)/2 -> 685.88433
A13: Plan managers — average during year | B13: =(0+B9)/2 -> 5.52 | C13: =(B9+C9)/2 -> 28.488 | D13: =(C9+D9)/2 -> 82.77984 | E13: =(D9+E9)/2 -> 178.44626 | F13: =(E9+F9)/2 -> 315.43271
A15: REVENUE
A16: Therapy orgs | B16: =B10*Assumptions!$B$11*Assumptions!$B$14*12 -> 22356 | C16: =C10*Assumptions!$B$11*Assumptions!$B$14*12 -> 151826.4 | D16: =D10*Assumptions!$B$11*Assumptions!$B$14*12 -> 528524.35 | E16: =E10*Assumptions!$B$11*Assumptions!$B$14*12 -> 1249181.4 | F16: =F10*Assumptions!$B$11*Assumptions!$B$14*12 -> 2239759.7
A17: Solo providers | B17: =B11*Assumptions!$B$15*12 -> 8390.4 | C17: =C11*Assumptions!$B$15*12 -> 77501.76 | D17: =D11*Assumptions!$B$15*12 -> 350633.36 | E17: =E11*Assumptions!$B$15*12 -> 950605.35 | F17: =F11*Assumptions!$B$15*12 -> 1859796.7
A18: Support/SIL orgs | B18: =B12*Assumptions!$B$16*12 -> 33120 | C18: =C12*Assumptions!$B$16*12 -> 257328 | D18: =D12*Assumptions!$B$16*12 -> 991751.04 | E18: =E12*Assumptions!$B$16*12 -> 2551780.9 | F18: =F12*Assumptions!$B$16*12 -> 4938367.2
A19: Plan managers | B19: =B13*Assumptions!$B$17*12 -> 82800 | C19: =C13*Assumptions!$B$17*12 -> 427320 | D19: =D13*Assumptions!$B$17*12 -> 1241697.6 | E19: =E13*Assumptions!$B$17*12 -> 2676693.9 | F19: =F13*Assumptions!$B$17*12 -> 4731490.6
A20: Total revenue | B20: =SUM(B16:B19) -> 146666.4 | C20: =SUM(C16:C19) -> 913976.16 | D20: =SUM(D16:D19) -> 3112606.3 | E20: =SUM(E16:E19) -> 7428261.6 | F20: =SUM(F16:F19) -> 13769414
A21: Revenue growth | B21: - | C21: =IFERROR(C20/B20-1,0) -> 5.231667 | D21: =IFERROR(D20/C20-1,0) -> 2.4055662 | E21: =IFERROR(E20/D20-1,0) -> 1.3865085 | F21: =IFERROR(F20/E20-1,0) -> 0.8536523
A23: COSTS AND PROFIT
A24: Cost of delivery | B24: =-(B20*Assumptions!$B$28+Assumptions!$B$29) -> -96399.952 | C24: =-(C20*Assumptions!$B$28+Assumptions!$B$29) -> -234515.71 | D24: =-(D20*Assumptions!$B$28+Assumptions!$B$29) -> -630269.14 | E24: =-(E20*Assumptions!$B$28+Assumptions!$B$29) -> -1407087.1 | F24: =-(F20*Assumptions!$B$28+Assumptions!$B$29) -> -2548494.6
A25: Gross profit | B25: =B20+B24 -> 50266.448 | C25: =C20+C24 -> 679460.45 | D25: =D20+D24 -> 2482337.2 | E25: =E20+E24 -> 6021174.5 | F25: =F20+F24 -> 11220920
A26: Gross margin | B26: =IFERROR(B25/B20,0) -> 0.3427264 | C26: =IFERROR(C25/C20,0) -> 0.74341157 | D26: =IFERROR(D25/D20,0) -> 0.79751081 | E26: =IFERROR(E25/E20,0) -> 0.81057653 | F26: =IFERROR(F25/F20,0) -> 0.81491627
A27: People | B27: =-Assumptions!B33*Assumptions!B34 -> -600000 | C27: =-Assumptions!C33*Assumptions!C34 -> -1236000 | D27: =-Assumptions!D33*Assumptions!D34 -> -2068755 | E27: =-Assumptions!E33*Assumptions!E34 -> -2786453 | F27: =-Assumptions!F33*Assumptions!F34 -> -3545346
A28: Sales and marketing | B28: =-MAX(B20*Assumptions!B35,Assumptions!B36) -> -300000 | C28: =-MAX(C20*Assumptions!C35,Assumptions!C36) -> -500000 | D28: =-MAX(D20*Assumptions!D35,Assumptions!D36) -> -750000 | E28: =-MAX(E20*Assumptions!E35,Assumptions!E36) -> -1188521.9 | F28: =-MAX(F20*Assumptions!F35,Assumptions!F36) -> -1927718
A29: Security, compliance and assurance | B29: =-Assumptions!B37 -> -120000 | C29: =-Assumptions!C37 -> -160000 | D29: =-Assumptions!D37 -> -200000 | E29: =-Assumptions!E37 -> -230000 | F29: =-Assumptions!F37 -> -260000
A30: Other general and administrative | B30: =-Assumptions!B33*Assumptions!B38 -> -36000 | C30: =-Assumptions!C33*Assumptions!C38 -> -72000 | D30: =-Assumptions!D33*Assumptions!D38 -> -123500 | E30: =-Assumptions!E33*Assumptions!E38 -> -161500 | F30: =-Assumptions!F33*Assumptions!F38 -> -210000
A31: EBITDA | B31: =B25+SUM(B27:B30) -> -1005733.6 | C31: =C25+SUM(C27:C30) -> -1288539.5 | D31: =D25+SUM(D27:D30) -> -659917.79 | E31: =E25+SUM(E27:E30) -> 1654699.6 | F31: =F25+SUM(F27:F30) -> 5277855.7
A32: EBITDA margin | B32: =IFERROR(B31/B20,0) -> -6.8572867 | C32: =IFERROR(C31/C20,0) -> -1.4098175 | D32: =IFERROR(D31/D20,0) -> -0.21201454 | E32: =IFERROR(E31/E20,0) -> 0.22275732 | F32: =IFERROR(F31/F20,0) -> 0.38330285
A33: Equipment purchased | B33: =-Assumptions!B33*Assumptions!$B$45 -> -16000 | C33: =-Assumptions!C33*Assumptions!$B$45 -> -32000 | D33: =-Assumptions!D33*Assumptions!$B$45 -> -52000 | E33: =-Assumptions!E33*Assumptions!$B$45 -> -68000 | F33: =-Assumptions!F33*Assumptions!$B$45 -> -84000
A34: Depreciation and amortisation | B34: =SUM(B33:B33)/Assumptions!$B$46 -> -5333.3333 | C34: =SUM(B33:C33)/Assumptions!$B$46 -> -16000 | D34: =SUM(B33:D33)/Assumptions!$B$46 -> -33333.333 | E34: =SUM(C33:E33)/Assumptions!$B$46 -> -50666.667 | F34: =SUM(D33:F33)/Assumptions!$B$46 -> -68000
A35: Profit before tax | B35: =B31+B34 -> -1011066.9 | C35: =C31+C34 -> -1304539.5 | D35: =D31+D34 -> -693251.13 | E35: =E31+E34 -> 1604033 | F35: =F31+F34 -> 5209855.7
A36: Carried-forward tax losses — opening | B36: =0 -> 0 | C36: =B39 -> 1011066.9 | D36: =C39 -> 2315606.4 | E36: =D39 -> 3008857.6 | F36: =E39 -> 1404824.6
A37: Losses used this year | B37: =MIN(B36,MAX(0,B35)) -> 0 | C37: =MIN(C36,MAX(0,C35)) -> 0 | D37: =MIN(D36,MAX(0,D35)) -> 0 | E37: =MIN(E36,MAX(0,E35)) -> 1604033 | F37: =MIN(F36,MAX(0,F35)) -> 1404824.6
A38: Taxable income | B38: =MAX(0,B35-B37) -> 0 | C38: =MAX(0,C35-C37) -> 0 | D38: =MAX(0,D35-D37) -> 0 | E38: =MAX(0,E35-E37) -> 0 | F38: =MAX(0,F35-F37) -> 3805031.1
A39: Carried-forward tax losses — closing | B39: =B36-B37+MAX(0,-B35) -> 1011066.9 | C39: =C36-C37+MAX(0,-C35) -> 2315606.4 | D39: =D36-D37+MAX(0,-D35) -> 3008857.6 | E39: =E36-E37+MAX(0,-E35) -> 1404824.6 | F39: =F36-F37+MAX(0,-F35) -> 0
A40: Company tax | B40: =-B38*Assumptions!$B$47 -> 0 | C40: =-C38*Assumptions!$B$47 -> 0 | D40: =-D38*Assumptions!$B$47 -> 0 | E40: =-E38*Assumptions!$B$47 -> 0 | F40: =-F38*Assumptions!$B$47 -> -951257.77
A41: NET PROFIT AFTER TAX | B41: =B35+B40 -> -1011066.9 | C41: =C35+C40 -> -1304539.5 | D41: =D35+D40 -> -693251.13 | E41: =E35+E40 -> 1604033 | F41: =F35+F40 -> 4258597.9
A43: CASH
A44: Add back depreciation and amortisation | B44: =-B34 -> 5333.3333 | C44: =-C34 -> 16000 | D44: =-D34 -> 33333.333 | E44: =-E34 -> 50666.667 | F44: =-F34 -> 68000
...

Sheet Scenarios
A1: Scenarios — four cases side by side
A2: Scenarios 3 and 4 assume the platform engine already exists (built for AoB) and cost only the incremental team. Standalone scenarios carry the full build.
A4: Scenario | B4: Y1 | C4: Y2 | D4: Y3 | E4: Y4 | F4: Y5
A5: 1 STANDALONE BASE
A6: Full team of 7→32. Own build, own infrastructure.
A7: Revenue | B7: 88320 | C7: 620598 | D7: 2270523 | E7: 5651820 | F7: 10720882
A8: EBITDA | B8: -1530578 | C8: -2346610 | D8: -2530871 | E8: -1174143 | F8: 1237757
A9: Net profit after tax | B9: -1539911 | C9: -2373276 | D9: -2584205 | E9: -1252810 | F9: 1133757
A10: Closing cash | B10: -1433987 | C10: -3772817 | D10: -6391145 | E10: -7827119 | F10: -6985039
A12: 2 STANDALONE LEAN
A13: Same adoption, team 6→23.
A14: Revenue | B14: 88320 | C14: 620598 | D14: 2270523 | E14: 5651820 | F14: 10720882
A15: EBITDA | B15: -1371578 | C15: -1856110 | D15: -1687696 | E15: 39720 | F15: 2847194
A16: Net profit after tax | B16: -1379578 | C16: -1877443 | D16: -1729030 | E16: -18946 | F16: 2771194
A17: Closing cash | B17: -1284055 | C17: -3147632 | D17: -4931772 | E17: -5156350 | F17: -2701347
A19: 3 SHARED ENGINE
A20: Second product on the existing platform. Team 4→18 covers only NDIS-specific work.
A21: Revenue | B21: 88320 | C21: 620598 | D21: 2270523 | E21: 5651820 | F21: 10720882
A22: EBITDA | B22: -1053578 | C22: -1529110 | D22: -1181791 | E22: 733357 | F22: 3741326
A23: Net profit after tax | B23: -1058911 | C23: -1545110 | D23: -1213791 | E23: 686690 | F23: 3543775
A24: Closing cash | B24: -984192 | C24: -2513508 | D24: -3794448 | E24: -3324820 | F24: -109715
A26: 4 SHARED ENGINE + PLAN-MANAGER CHANNEL
A27: Plan managers as an aggregation channel reach the 46,000 unregistered solos.
A28: Revenue | B28: 146666 | C28: 913976 | D28: 3112606 | E28: 7428262 | F28: 13769414
A29: EBITDA | B29: -1005734 | C29: -1288540 | D29: -659918 | E29: 1654699 | F29: 5277849
A30: Net profit after tax | B30: -1011067 | C30: -1304540 | D30: -693251 | E30: 1604032 | F30: 4258593
A31: Closing cash | B31: -941080 | C31: -2248886 | D31: -3042590 | E31: -1705252 | F31: 2152683
A34: THE CEILING
A35: Therapy orgs: 7,274 × $1,620/yr | B35: 11783880
A36: Solo therapy: 46,330 × $228/yr | B36: 10563240
A37: Support/SIL orgs: ~10,000 × $7,200/yr | B37: 72000000 | D37: The count and price are both estimates — this line dominates and is the least certain
A38: Plan managers: ~1,100 × $12,000/yr | B38: 13200000
A39: TOTAL AUSTRALIAN CEILING (100% share) | B39: 107547120 | D39: Roughly double the AoB ceiling of $37.6–51.7m
A40: A strong 20% share | B40: 21509424
A42: All adoption figures are assumptions with no evidential basis. The support-org price ($600/month average) is the single most consequential guess in this workbook.

Sheet Unit Economics
A1: Unit economics — one therapy org, one support org
A4: THERAPY ORG
A5: Revenue per year | B5: =Assumptions!$B$11*Assumptions!$B$14*12 -> 1620 | D5: 3 practitioners × $45 × 12
A6: Delivery cost | B6: =-B5*Assumptions!$B$28 -> -291.6
A7: Gross profit per year | B7: =B5+B6 -> 1328.4
A8: As % of their avg NDIS billings ($225k) | B8: =B5/225000 -> 0.0072 | D8: Well under 1% — an easy line item
A9: SUPPORT/SIL ORG
A10: Revenue per year | B10: =Assumptions!$B$16*12 -> 7200 | D10: Tiered average
A11: Delivery cost | B11: =-B10*Assumptions!$B$28 -> -1296
A12: Gross profit per year | B12: =B10+B11 -> 5904
A13: As % of a $2m support org’s NDIS revenue | B13: =B10/2000000 -> 0.0036 | D13: 0.36% of revenue for audit-proof evidence
A14: SOLO PROVIDER
A15: Revenue per year | B15: =Assumptions!$B$15*12 -> 228 | D15: $19/month self-serve
A16: As % of avg solo NDIS billings ($22k) | B16: =B15/22000 -> 0.010363636 | D16: ~1% — the practical ceiling for this tier
